Workbook

Sheet Mapeamento BRM
A1: Domínio | B1: Macro grupo | C1: Grupo | D1: Campo solicitado | E1: Exemplo | F1: Classe BRM de referência | G1: Tabela core BRM de referência | H1: Tabela custom sugerida | I1: Observação de mapeamento
A2: Tributário | B2: Estadual | C2: Impostos Estaduais | D2: Base de cálculo ICMS | E2: R$ 4.890,00 | F2: /item; /event/billing/tax | G2: ITEM_T; EVENT_T; EVENT_BAL_IMPACTS_T | H2: c_item_st_tax_t | I2: Base, alíquota e valor tributário são referência fiscal do item/evento; normalmente demandam extensão/integração fiscal.
A3: Tributário | B3: Estadual | C3: Impostos Estaduais | D3: Percentual ICMS | E3: 18,00% | F3: /item; /event/billing/tax | G3: ITEM_T; EVENT_T; EVENT_BAL_IMPACTS_T | H3: c_item_st_tax_t | I3: Base, alíquota e valor tributário são referência fiscal do item/evento; normalmente demandam extensão/integração fiscal.
A4: Tributário | B4: Estadual | C4: Impostos Estaduais | D4: Valor ICMS | E4: R$ 880,20 | F4: /item; /event/billing/tax | G4: ITEM_T; EVENT_T; EVENT_BAL_IMPACTS_T | H4: c_item_st_tax_t | I4: Base, alíquota e valor tributário são referência fiscal do item/evento; normalmente demandam extensão/integração fiscal.
A5: Tributário | B5: Estadual | C5: Ref. Tribut. - IBS Estadual | D5: Base IBS Estadual | E5: R$ 4.890,00 | F5: /item; /event/billing/tax | G5: ITEM_T; EVENT_T; EVENT_BAL_IMPACTS_T | H5: c_item_ibs_st_t | I5: Base, alíquota e valor tributário são referência fiscal do item/evento; normalmente demandam extensão/integração fiscal.
A6: Tributário | B6: Estadual | C6: Ref. Tribut. - IBS Estadual | D6: Percentual do IBS Estadual | E6: 9,70% | F6: /item; /event/billing/tax | G6: ITEM_T; EVENT_T; EVENT_BAL_IMPACTS_T | H6: c_item_ibs_st_t | I6: Base, alíquota e valor tributário são referência fiscal do item/evento; normalmente demandam extensão/integração fiscal.
A7: Tributário | B7: Estadual | C7: Ref. Tribut. - IBS Estadual | D7: Valor do IBS Estadual | E7: R$ 474,33 | F7: /item; /event/billing/tax | G7: ITEM_T; EVENT_T; EVENT_BAL_IMPACTS_T | H7: c_item_ibs_st_t | I7: Base, alíquota e valor tributário são referência fiscal do item/evento; normalmente demandam extensão/integração fiscal.
A8: Tributário | B8: Estadual | C8: Fundos e Contr. Set. | D8: Base FCP | E8: R$ 4.890,00 | F8: /item; /event/billing/tax | G8: ITEM_T; EVENT_T; EVENT_BAL_IMPACTS_T | H8: c_item_sector_fund_t | I8: Base, alíquota e valor tributário são referência fiscal do item/evento; normalmente demandam extensão/integração fiscal.
A9: Tributário | B9: Estadual | C9: Fundos e Contr. Set. | D9: Percentual FCP | E9: 2,00% | F9: /item; /event/billing/tax | G9: ITEM_T; EVENT_T; EVENT_BAL_IMPACTS_T | H9: c_item_sector_fund_t | I9: Base, alíquota e valor tributário são referência fiscal do item/evento; normalmente demandam extensão/integração fiscal.
A10: Tributário | B10: Estadual | C10: Fundos e Contr. Set. | D10: Valor FCP | E10: R$ 97,80 | F10: /item; /event/billing/tax | G10: ITEM_T; EVENT_T; EVENT_BAL_IMPACTS_T | H10: c_item_sector_fund_t | I10: Base, alíquota e valor tributário são referência fiscal do item/evento; normalmente demandam extensão/integração fiscal.
A11: Tributário | B11: Federal | C11: Impostos Federais | D11: Base de cálculo PIS | E11: R$ 4.009,80 | F11: /item; /event/billing/tax | G11: ITEM_T; EVENT_T; EVENT_BAL_IMPACTS_T | H11: c_item_fed_tax_t | I11: Base, alíquota e valor tributário são referência fiscal do item/evento; normalmente demandam extensão/integração fiscal.
A12: Tributário | B12: Federal | C12: Impostos Federais | D12: Percentual PIS | E12: 1,65% | F12: /item; /event/billing/tax | G12: ITEM_T; EVENT_T; EVENT_BAL_IMPACTS_T | H12: c_item_fed_tax_t | I12: Base, alíquota e valor tributário são referência fiscal do item/evento; normalmente demandam extensão/integração fiscal.
... A71: Não tributária | B71: Validação e comunicação | C71: Contato do solicitante | D71: Telefone Solicitante | E71: 1132547812 | F71: /invoice | G71: INVOICE_T | H71: c_invoice_requester_t | I71: Metadados/comunicação de documento; solicitante tende a exigir extensão/customização sobre invoice.

Sheet Resumo
A1: Resumo do mapeamento
A3: Total de campos | B3: 70 | D3: Classe BRM de referência | E3: Qtd. campos
A4: Campos tributários | B4: 43 | D4: /account | E4: 4
A5: Campos não tributários | B5: 27 | D5: /bill | E5: 2
D6: /bill; /invoice | E6: 2
D7: /billinfo; /purchased_product | E7: 1
D8: /invoice | E8: 10
D9: /item; /event | E9: 4
D10: /item; /event/billing/tax | E10: 41
D11: /product; /purchased_product | E11: 5
D12: /purchased_product | E12: 1

Sheet Referências
A1: Uso | B1: Fonte
A2: Oracle BRM 15.1 Storable Class Reference | B2: https://docs.oracle.com/en/industries/communications/billing-revenue/15.1/storable-class-ref/index.html
A3: Oracle BRM 15.1 Mapping Legacy Data to the BRM Data Schema | B3: https://docs.oracle.com/en/industries/communications/billing-revenue/15.1/migrating-accounts/mapping-legacy-data-brm-data-schema1.html
A4: Oracle BRM Developer's Reference: Storable Class-to-SQL Mapping | B4: https://docs.oracle.com/en/industries/communications/billing-revenue/12.0/dev-reference/storable-class-sql-mapping1.html
A5: Nota | B5: A tabela é referência funcional para desenho de tela e extensão FlexBill. O mapeamento físico final deve ser validado no ambiente BRM, especialmente em BRM_HOME/sys/dd/data/dd_objects.source e nas customizações fiscais existentes.
A6: Dicionário técnico-funcional gerado | B6: Derivado da primeira aba 'Mapeamento BRM' do arquivo mapeamento_campos_flexbill_oracle_brm.xlsx.

Sheet Dicionário API
A1: Dicionário técnico-funcional — FlexBill x Oracle BRM
A2: Evolução da lista de campos para contrato de API: tipo, JSON path, validação, origem BRM/custom, regra de cálculo e sensibilidade.
A3: ID do campo | B3: Campo solicitado | C3: Nome API | D3: JSON path | E3: Domínio | F3: Macro grupo | G3: Grupo | H3: Nível funcional | I3: Tipo de dado | J3: Formato/máscara | K3: Obrigatoriedade | L3: Validação | M3: Exemplo | N3: Origem BRM | O3: Tabela core BRM | P3: Origem custom | Q3: Regra de cálculo/preenchimento | R3: Sensibilidade | S3: Prioridade | T3: Status documentação | U3: Observação de qualidade | V3: Observação original
A4: FLXBRM-001 | B4: Base de cálculo ICMS | C4: icmsBaseAmount | D4: invoice.items[].taxDetails[?taxType='ICMS'].baseAmount | E4: Tributário | F4: Estadual | G4: Impostos Estaduais | H4: TaxDetail | I4: number | J4: Decimal monetário com 2 casas; currency em BRL no contexto | K4: Condicional | L4: Valor monetário >= 0; obrigatório quando o tributo/fundo/retenção for aplicável. | M4: R$ 4.890,00 | N4: /item; /event/billing/tax | O4: ITEM_T; EVENT_T; EVENT_BAL_IMPACTS_T | P4: c_item_st_tax_t | Q4: Gerar somente quando o tributo ICMS for aplicável ao item; amount deve ser derivado de baseAmount e rate ou recebido de motor fiscal. | R4: Fiscal | S4: P0 | T4: Documentado | V4: Base, alíquota e valor tributário são referência fiscal do item/evento; normalmente demandam extensão/integração fiscal.
A5: FLXBRM-002 | B5: Percentual ICMS | C5: icmsRate | D5: invoice.items[].taxDetails[?taxType='ICMS'].rate | E5: Tributário | F5: Estadual | G5: Impostos Estaduais | H5: TaxDetail | I5: number | J5: Decimal percentual com 2 casas; sem símbolo % no JSON | K5: Condicional | L5: Número entre 0 e 100; máximo 4 casas se necessário; não enviar símbolo %. Validar amount = baseAmount * rate / 100. | M5: 18,00% | N5: /item; /event/billing/tax | O5: ITEM_T; EVENT_T; EVENT_BAL_IMPACTS_T | P5: c_item_st_tax_t | Q5: Gerar somente quando o tributo ICMS for aplicável ao item; amount deve ser derivado de baseAmount e rate ou recebido de motor fiscal. | R5: Fiscal | S5: P0 | T5: Documentado | V5: Base, alíquota e valor tributário são referência fiscal do item/evento; normalmente demandam extensão/integração fiscal.
A6: FLXBRM-003 | B6: Valor ICMS | C6: icmsAmount | D6: invoice.items[].taxDetails[?taxType='ICMS'].amount | E6: Tributário | F6: Estadual | G6: Impostos Estaduais | H6: TaxDetail | I6: number | J6: Decimal monetário com 2 casas; currency em BRL no contexto | K6: Condicional | L6: Valor monetário >= 0; reconciliar com baseAmount e rate, tolerância recomendada de R$ 0,01. | M6: R$ 880,20 | N6: /item; /event/billing/tax | O6: ITEM_T; EVENT_T; EVENT_BAL_IMPACTS_T | P6: c_item_st_tax_t | Q6: Gerar somente quando o tributo ICMS for aplicável ao item; amount deve ser derivado de baseAmount e rate ou recebido de motor fiscal. | R6: Fiscal | S6: P0 | T6: Documentado | V6: Base, alíquota e valor tributário são referência fiscal do item/evento; normalmente demandam extensão/integração fiscal.
A7: FLXBRM-004 | B7: Base IBS Estadual | C7: ibsStateBaseAmount | D7: invoice.items[].taxDetails[?taxType='IBS_ESTADUAL'].baseAmount | E7: Tributário | F7: Estadual | G7: Ref. Tribut. - IBS Estadual | H7: TaxDetail | I7: number | J7: Decimal monetário com 2 casas; currency em BRL no contexto | K7: Condicional | L7: Valor monetário >= 0; obrigatório quando o tributo/fundo/retenção for aplicável. | M7: R$ 4.890,00 | N7: /item; /event/billing/tax | O7: ITEM_T; EVENT_T; EVENT_BAL_IMPACTS_T | P7: c_item_ibs_st_t | Q7: Gerar somente quando o tributo IBS_ESTADUAL for aplicável ao item; amount deve ser derivado de baseAmount e rate ou recebido de motor fiscal. | R7: Fiscal | S7: P0 | T7: Documentado | V7: Base, alíquota e valor tributário são referência fiscal do item/evento; normalmente demandam extensão/integração fiscal.
A8: FLXBRM-005 | B8: Percentual do IBS Estadual | C8: ibsStateRate | D8: invoice.items[].taxDetails[?taxType='IBS_ESTADUAL'].rate | E8: Tributário | F8: Estadual | G8: Ref. Tribut. - IBS Estadual | H8: TaxDetail | I8: number | J8: Decimal percentual com 2 casas; sem símbolo % no JSON | K8: Condicional | L8: Número entre 0 e 100; máximo 4 casas se necessário; não enviar símbolo %. Validar amount = baseAmount * rate / 100. | M8: 9,70% | N8: /item; /event/billing/tax | O8: ITEM_T; EVENT_T; EVENT_BAL_IMPACTS_T | P8: c_item_ibs_st_t | Q8: Gerar somente quando o tributo IBS_ESTADUAL for aplicável ao item; amount deve ser derivado de baseAmount e rate ou recebido de motor fiscal. | R8: Fiscal | S8: P0 | T8: Documentado | V8: Base, alíquota e valor tributário são referência fiscal do item/evento; normalmente demandam extensão/integração fiscal.
A9: FLXBRM-006 | B9: Valor do IBS Estadual | C9: ibsStateAmount | D9: invoice.items[].taxDetails[?taxType='IBS_ESTADUAL'].amount | E9: Tributário | F9: Estadual | G9: Ref. Tribut. - IBS Estadual | H9: TaxDetail | I9: number | J9: Decimal monetário com 2 casas; currency em BRL no contexto | K9: Condicional | L9: Valor monetário >= 0; reconciliar com baseAmount e rate, tolerância recomendada de R$ 0,01. | M9: R$ 474,33 | N9: /item; /event/billing/tax | O9: ITEM_T; EVENT_T; EVENT_BAL_IMPACTS_T | P9: c_item_ibs_st_t | Q9: Gerar somente quando o tributo IBS_ESTADUAL for aplicável ao item; amount deve ser derivado de baseAmount e rate ou recebido de motor fiscal. | R9: Fiscal | S9: P0 | T9: Documentado | V9: Base, alíquota e valor tributário são referência fiscal do item/evento; normalmente demandam extensão/integração fiscal.
A10: FLXBRM-007 | B10: Base FCP | C10: fcpBaseAmount | D10: invoice.items[].sectorFunds[?fundType='FCP'].baseAmount | E10: Tributário | F10: Estadual | G10: Fundos e Contr. Set. | H10: SectorFund | I10: number | J10: Decimal monetário com 2 casas; currency em BRL no contexto | K10: Condicional | L10: Valor monetário >= 0; obrigatório quando o tributo/fundo/retenção for aplicável. | M10: R$ 4.890,00 | N10: /item; /event/billing/tax | O10: ITEM_T; EVENT_T; EVENT_BAL_IMPACTS_T | P10: c_item_sector_fund_t | Q10: Gerar somente quando o fundo FCP for aplicável ao item; valor calculado a partir de baseAmount e rate. | R10: Fiscal | S10: P0 | T10: Documentado | V10: Base, alíquota e valor tributário são referência fiscal do item/evento; normalmente demandam extensão/integração fiscal.
A11: FLXBRM-008 | B11: Percentual FCP | C11: fcpRate | D11: invoice.items[].sectorFunds[?fundType='FCP'].rate | E11: Tributário | F11: Estadual | G11: Fundos e Contr. Set. | H11: SectorFund | I11: number | J11: Decimal percentual com 2 casas; sem símbolo % no JSON | K11: Condicional | L11: Número entre 0 e 100; máximo 4 casas se necessário; não enviar símbolo %. Validar amount = baseAmount * rate / 100. | M11: 2,00% | N11: /item; /event/billing/tax | O11: ITEM_T; EVENT_T; EVENT_BAL_IMPACTS_T | P11: c_item_sector_fund_t | Q11: Gerar somente quando o fundo FCP for aplicável ao item; valor calculado a partir de baseAmount e rate. | R11: Fiscal | S11: P0 | T11: Documentado | V11: Base, alíquota e valor tributário são referência fiscal do item/evento; normalmente demandam extensão/integração fiscal.
A12: FLXBRM-009 | B12: Valor FCP | C12: fcpAmount | D12: invoice.items[].sectorFunds[?fundType='FCP'].amount | E12: Tributário | F12: Estadual | G12: Fundos e Contr. Set. | H12: SectorFund | I12: number | J12: Decimal monetário com 2 casas; currency em BRL no contexto | K12: Condicional | L12: Valor monetário >= 0; reconciliar com baseAmount e rate, tolerância recomendada de R$ 0,01. | M12: R$ 97,80 | N12: /item; /event/billing/tax | O12: ITEM_T; EVENT_T; EVENT_BAL_IMPACTS_T | P12: c_item_sector_fund_t | Q12: Gerar somente quando o fundo FCP for aplicável ao item; valor calculado a partir de baseAmount e rate. | R12: Fiscal | S12: P0 | T12: Documentado | V12: Base, alíquota e valor tributário são referência fiscal do item/evento; normalmente demandam extensão/integração fiscal.
A13: FLXBRM-010 | B13: Base de cálculo PIS | C13: pisBaseAmount | D13: invoice.items[].taxDetails[?taxType='PIS'].baseAmount | E13: Tributário | F13: Federal | G13: Impostos Federais | H13: TaxDetail | I13: number | J13: Decimal monetário com 2 casas; currency em BRL no contexto | K13: Condicional | L13: Valor monetário >= 0; obrigatório quando o tributo/fundo/retenção for aplicável. | M13: R$ 4.009,80 | N13: /item; /event/billing/tax | O13: ITEM_T; EVENT_T; EVENT_BAL_IMPACTS_T | P13: c_item_fed_tax_t | Q13: Gerar somente quando o tributo PIS for aplicável ao item; amount deve ser derivado de baseAmount e rate ou recebido de motor fiscal. | R13: Fiscal | S13: P0 | T13: Documentado | V13: Base, alíquota e valor tributário são referência fiscal do item/evento; normalmente demandam extensão/integração fiscal.
A14: FLXBRM-011 | B14: Percentual PIS | C14: pisRate | D14: invoice.items[].taxDetails[?taxType='PIS'].rate | E14: Tributário | F14: Federal | G14: Impostos Federais | H14: TaxDetail | I14: number | J14: Decimal percentual com 2 casas; sem símbolo % no JSON | K14: Condicional | L14: Número entre 0 e 100; máximo 4 casas se necessário; não enviar símbolo %. Validar amount = baseAmount * rate / 100. | M14: 1,65% | N14: /item; /event/billing/tax | O14: ITEM_T; EVENT_T; EVENT_BAL_IMPACTS_T | P14: c_item_fed_tax_t | Q14: Gerar somente quando o tributo PIS for aplicável ao item; amount deve ser derivado de baseAmount e rate ou recebido de motor fiscal. | R14: Fiscal | S14: P0 | T14: Documentado | V14: Base, alíquota e valor tributário são referência fiscal do item/evento; normalmente demandam extensão/integração fiscal.
A15: FLXBRM-012 | B15: Valor PIS | C15: pisAmount | D15: invoice.items[].taxDetails[?taxType='PIS'].amount | E15: Tributário | F15: Federal | G15: Impostos Federais | H15: TaxDetail | I15: number | J15: Decimal monetário com 2 casas; currency em BRL no contexto | K15: Condicional | L15: Valor monetário >= 0; reconciliar com baseAmount e rate, tolerância recomendada de R$ 0,01. | M15: R$ 66,16 | N15: /item; /event/billing/tax | O15: ITEM_T; EVENT_T; EVENT_BAL_IMPACTS_T | P15: c_item_fed_tax_t | Q15: Gerar somente quando o tributo PIS for aplicável ao item; amount deve ser derivado de baseAmount e rate ou recebido de motor fiscal. | R15: Fiscal | S15: P0 | T15: Documentado | V15: Base, alíquota e valor tributário são referência fiscal do item/evento; normalmente demandam extensão/integração fiscal.
A16: FLXBRM-013 | B16: Base de cálculo COFINS | C16: cofinsBaseAmount | D16: invoice.items[].taxDetails[?taxType='COFINS'].baseAmount | E16: Tributário | F16: Federal | G16: Impostos Federais | H16: TaxDetail | I16: number | J16: Decimal monetário com 2 casas; currency em BRL no contexto | K16: Condicional | L16: Valor monetário >= 0; obrigatório quando o tributo/fundo/retenção for aplicável. | M16: R$ 4.009,80 | N16: /item; /event/billing/tax | O16: ITEM_T; EVENT_T; EVENT_BAL_IMPACTS_T | P16: c_item_fed_tax_t | Q16: Gerar somente quando o tributo COFINS for aplicável ao item; amount deve ser derivado de baseAmount e rate ou recebido de motor fiscal. | R16: Fiscal | S16: P0 | T16: Documentado | V16: Base, alíquota e valor tributário são referência fiscal do item/evento; normalmente demandam extensão/integração fiscal.
A17: FLXBRM-014 | B17: Valor COFINS | C17: cofinsAmount | D17: invoice.items[].taxDetails[?taxType='COFINS'].amount | E17: Tributário | F17: Federal | G17: Impostos Federais | H17: TaxDetail | I17: number | J17: Decimal monetário com 2 casas; currency em BRL no contexto | K17: Condicional | L17: Valor monetário >= 0; reconciliar com baseAmount e rate, tolerância recomendada de R$ 0,01. | M17: R$ 304,74 | N17: /item; /event/billing/tax | O17: ITEM_T; EVENT_T; EVENT_BAL_IMPACTS_T | P17: c_item_fed_tax_t | Q17: Gerar somente quando o tributo COFINS for aplicável ao item; amount deve ser derivado de baseAmount e rate ou recebido de motor fiscal. | R17: Fiscal | S17: P0 | T17: Documentado | U17: Verificar se Percentual COFINS deve ser incluído; PIS possui base/percentual/valor. | V17: Base, alíquota e valor tributário são referência fiscal do item/evento; normalmente demandam extensão/integração fiscal.
A18: FLXBRM-015 | B18: Base do CBS | C18: cbsBaseAmount | D18: invoice.items[].taxDetails[?taxType='CBS'].baseAmount | E18: Tributário | F18: Federal | G18: Ref. Tribut. - Federal | H18: TaxDetail | I18: number | J18: Decimal monetário com 2 casas; currency em BRL no contexto | K18: Condicional | L18: Valor monetário >= 0; obrigatório quando o tributo/fundo/retenção for aplicável. | M18: A informar | N18: /item; /event/billing/tax | O18: ITEM_T; EVENT_T; EVENT_BAL_IMPACTS_T | P18: c_item_cbs_ref_t | Q18: Gerar somente quando o tributo CBS for aplicável ao item; amount deve ser derivado de baseAmount e rate ou recebido de motor fiscal. | R18: Fiscal | S18: P0 | T18: Pendente exemplo | U18: Completar exemplo e regra de origem antes de publicar contrato. | V18: Base, alíquota e valor tributário são referência fiscal do item/evento; normalmente demandam extensão/integração fiscal.
A19: FLXBRM-016 | B19: Percentual do CBS | C19: cbsRate | D19: invoice.items[].taxDetails[?taxType='CBS'].rate | E19: Tributário | F19: Federal | G19: Ref. Tribut. - Federal | H19: TaxDetail | I19: number | J19: Decimal percentual com 2 casas; sem símbolo % no JSON | K19: Condicional | L19: Número entre 0 e 100; máximo 4 casas se necessário; não enviar símbolo %. Validar amount = baseAmount * rate / 100. | M19: 8,80% | N19: /item; /event/billing/tax | O19: ITEM_T; EVENT_T; EVENT_BAL_IMPACTS_T | P19: c_item_cbs_ref_t | Q19: Gerar somente quando o tributo CBS for aplicável ao item; amount deve ser derivado de baseAmount e rate ou recebido de motor fiscal. | R19: Fiscal | S19: P0 | T19: Documentado | V19: Base, alíquota e valor tributário são referência fiscal do item/evento; normalmente demandam extensão/integração fiscal.
A20: FLXBRM-017 | B20: Valor do CBS | C20: cbsAmount | D20: invoice.items[].taxDetails[?taxType='CBS'].amount | E20: Tributário | F20: Federal | G20: Ref. Tribut. - Federal | H20: TaxDetail | I20: number | J20: Decimal monetário com 2 casas; currency em BRL no contexto | K20: Condicional | L20: Valor monetário >= 0; reconciliar com baseAmount e rate, tolerância recomendada de R$ 0,01. | M20: R$ 430,32 | N20: /item; /event/billing/tax | O20: ITEM_T; EVENT_T; EVENT_BAL_IMPACTS_T | P20: c_item_cbs_ref_t | Q20: Gerar somente quando o tributo CBS for aplicável ao item; amount deve ser derivado de baseAmount e rate ou recebido de motor fiscal. | R20: Fiscal | S20: P0 | T20: Documentado | V20: Base, alíquota e valor tributário são referência fiscal do item/evento; normalmente demandam extensão/integração fiscal.
A21: FLXBRM-018 | B21: Retenção Base IRRF | C21: irrfWithholdingBaseAmount | D21: invoice.items[].withholdingTaxes[?taxType='IRRF'].baseAmount | E21: Tributário | F21: Federal | G21: Retenções Federais | H21: WithholdingTax | I21: number | J21: Decimal monetário com 2 casas; currency em BRL no contexto | K21: Condicional | L21: Valor monetário >= 0; obrigatório quando o tributo/fundo/retenção for aplicável. | M21: R$ 1.250,00 | N21: /item; /event/billing/tax | O21: ITEM_T; EVENT_T; EVENT_BAL_IMPACTS_T | P21: c_item_fed_wht_t | Q21: Gerar somente quando houver retenção IRRF; base, percentual e valor devem vir da regra fiscal/retenção aplicada ao item. | R21: Fiscal | S21: P0 | T21: Documentado | V21: Base, alíquota e valor tributário são referência fiscal do item/evento; normalmente demandam extensão/integração fiscal.
A22: FLXBRM-019 | B22: Retenção Percentual IRRF | C22: irrfWithholdingRate | D22: invoice.items[].withholdingTaxes[?taxType='IRRF'].rate | E22: Tributário | F22: Federal | G22: Retenções Federais | H22: WithholdingTax | I22: number | J22: Decimal percentual com 2 casas; sem símbolo % no JSON | K22: Condicional | L22: Número entre 0 e 100; máximo 4 casas se necessário; não enviar símbolo %. Validar amount = baseAmount * rate / 100. | M22: 1,50% | N22: /item; /event/billing/tax | O22: ITEM_T; EVENT_T; EVENT_BAL_IMPACTS_T | P22: c_item_fed_wht_t | Q22: Gerar somente quando houver retenção IRRF; base, percentual e valor devem vir da regra fiscal/retenção aplicada ao item. | R22: Fiscal | S22: P0 | T22: Documentado | V22: Base, alíquota e valor tributário são referência fiscal do item/evento; normalmente demandam extensão/integração fiscal.
A23: FLXBRM-020 | B23: Retenção Valor IRRF | C23: irrfWithholdingAmount | D23: invoice.items[].withholdingTaxes[?taxType='IRRF'].amount | E23: Tributário | F23: Federal | G23: Retenções Federais | H23: WithholdingTax | I23: number | J23: Decimal monetário com 2 casas; currency em BRL no contexto | K23: Condicional | L23: Valor monetário >= 0; reconciliar com baseAmount e rate, tolerância recomendada de R$ 0,01. | M23: R$ 18,75 | N23: /item; /event/billing/tax | O23: ITEM_T; EVENT_T; EVENT_BAL_IMPACTS_T | P23: c_item_fed_wht_t | Q23: Gerar somente quando houver retenção IRRF; base, percentual e valor devem vir da regra fiscal/retenção aplicada ao item. | R23: Fiscal | S23: P0 | T23: Documentado | V23: Base, alíquota e valor tributário são referência fiscal do item/evento; normalmente demandam extensão/integração fiscal.
A24: FLXBRM-021 | B24: Retenção Base CSLL | C24: csllWithholdingBaseAmount | D24: invoice.items[].withholdingTaxes[?taxType='CSLL'].baseAmount | E24: Tributário | F24: Federal | G24: Retenções Federais | H24: WithholdingTax | I24: number | J24: Decimal monetário com 2 casas; currency em BRL no contexto | K24: Condicional | L24: Valor monetário >= 0; obrigatório quando o tributo/fundo/retenção for aplicável. | M24: A informar | N24: /item; /event/billing/tax | O24: ITEM_T; EVENT_T; EVENT_BAL_IMPACTS_T | P24: c_item_fed_wht_t | Q24: Gerar somente quando houver retenção CSLL; base, percentual e valor devem vir da regra fiscal/retenção aplicada ao item. | R24: Fiscal | S24: P0 | T24: Pendente exemplo | U24: Completar exemplo e regra de origem antes de publicar contrato. | V24: Base, alíquota e valor tributário são referência fiscal do item/evento; normalmente demandam extensão/integração fiscal.
A25: FLXBRM-022 | B25: Retenção Percentual CSLL | C25: csllWithholdingRate | D25: invoice.items[].withholdingTaxes[?taxType='CSLL'].rate | E25: Tributário | F25: Federal | G25: Retenções Federais | H25: WithholdingTax | I25: number | J25: Decimal percentual com 2 casas; sem símbolo % no JSON | K25: Condicional | L25: Número entre 0 e 100; máximo 4 casas se necessário; não enviar símbolo %. Validar amount = baseAmount * rate / 100. | M25: 1,00% | N25: /item; /event/billing/tax | O25: ITEM_T; EVENT_T; EVENT_BAL_IMPACTS_T | P25: c_item_fed_wht_t | Q25: Gerar somente quando houver retenção CSLL; base, percentual e valor devem vir da regra fiscal/retenção aplicada ao item. | R25: Fiscal | S25: P0 | T25: Documentado | V25: Base, alíquota e valor tributário são referência fiscal do item/evento; normalmente demandam extensão/integração fiscal.
A26: FLXBRM-023 | B26: Retenção Valor CSLL | C26: csllWithholdingAmount | D26: invoice.items[].withholdingTaxes[?taxType='CSLL'].amount | E26: Tributário | F26: Federal | G26: Retenções Federais | H26: WithholdingTax | I26: number | J26: Decimal monetário com 2 casas; currency em BRL no contexto | K26: Condicional | L26: Valor monetário >= 0; reconciliar com baseAmount e rate, tolerância recomendada de R$ 0,01. | M26: R$ 12,50 | N26: /item; /event/billing/tax | O26: ITEM_T; EVENT_T; EVENT_BAL_IMPACTS_T | P26: c_item_fed_wht_t | Q26: Gerar somente quando houver retenção CSLL; base, percentual e valor devem vir da regra fiscal/retenção aplicada ao item. | R26: Fiscal | S26: P0 | T26: Documentado | V26: Base, alíquota e valor tributário são referência fiscal do item/evento; normalmente demandam extensão/integração fiscal.
A27: FLXBRM-024 | B27: Retenção Base PIS | C27: pisBaseAmount | D27: invoice.items[].withholdingTaxes[?taxType='PIS'].baseAmount | E27: Tributário | F27: Federal | G27: Retenções Federais | H27: WithholdingTax | I27: number | J27: Decimal monetário com 2 casas; currency em BRL no contexto | K27: Condicional | L27: Valor monetário >= 0; obrigatório quando o tributo/fundo/retenção for aplicável. | M27: R$ 1.250,00 | N27: /item; /event/billing/tax | O27: ITEM_T; EVENT_T; EVENT_BAL_IMPACTS_T | P27: c_item_fed_wht_t | Q27: Gerar somente quando houver retenção PIS; base, percentual e valor devem vir da regra fiscal/retenção aplicada ao item. | R27: Fiscal | S27: P0 | T27: Documentado | V27: Base, alíquota e valor tributário são referência fiscal do item/evento; normalmente demandam extensão/integração fiscal.
A28: FLXBRM-025 | B28: Retenção Percentual PIS | C28: pisRate | D28: invoice.items[].withholdingTaxes[?taxType='PIS'].rate | E28: Tributário | F28: Federal | G28: Retenções Federais | H28: WithholdingTax | I28: number | J28: Decimal percentual com 2 casas; sem símbolo % no JSON | K28: Condicional | L28: Número entre 0 e 100; máximo 4 casas se necessário; não enviar símbolo %. Validar amount = baseAmount * rate / 100. | M28: 0,65% | N28: /item; /event/billing/tax | O28: ITEM_T; EVENT_T; EVENT_BAL_IMPACTS_T | P28: c_item_fed_wht_t | Q28: Gerar somente quando houver retenção PIS; base, percentual e valor devem vir da regra fiscal/retenção aplicada ao item. | R28: Fiscal | S28: P0 | T28: Documentado | V28: Base, alíquota e valor tributário são referência fiscal do item/evento; normalmente demandam extensão/integração fiscal.
A29: FLXBRM-026 | B29: Retenção Valor PIS | C29: pisAmount | D29: invoice.items[].withholdingTaxes[?taxType='PIS'].amount | E29: Tributário | F29: Federal | G29: Retenções Federais | H29: WithholdingTax | I29: number | J29: Decimal monetário com 2 casas; currency em BRL no contexto | K29: Condicional | L29: Valor monetário >= 0; reconciliar com baseAmount e rate, tolerância recomendada de R$ 0,01. | M29: R$ 8,13 | N29: /item; /event/billing/tax | O29: ITEM_T; EVENT_T; EVENT_BAL_IMPACTS_T | P29: c_item_fed_wht_t | Q29: Gerar somente quando houver retenção PIS; base, percentual e valor devem vir da regra fiscal/retenção aplicada ao item. | R29: Fiscal | S29: P0 | T29: Documentado | V29: Base, alíquota e valor tributário são referência fiscal do item/evento; normalmente demandam extensão/integração fiscal.
A30: FLXBRM-027 | B30: Retenção Base COFINS | C30: cofinsBaseAmount | D30: invoice.items[].withholdingTaxes[?taxType='COFINS'].baseAmount | E30: Tributário | F30: Federal | G30: Retenções Federais | H30: WithholdingTax | I30: number | J30: Decimal monetário com 2 casas; currency em BRL no contexto | K30: Condicional | L30: Valor monetário >= 0; obrigatório quando o tributo/fundo/retenção for aplicável. | M30: R$ 1.250,00 | N30: /item; /event/billing/tax | O30: ITEM_T; EVENT_T; EVENT_BAL_IMPACTS_T | P30: c_item_fed_wht_t | Q30: Gerar somente quando houver retenção COFINS; base, percentual e valor devem vir da regra fiscal/retenção aplicada ao item. | R30: Fiscal | S30: P0 | T30: Documentado | V30: Base, alíquota e valor tributário são referência fiscal do item/evento; normalmente demandam extensão/integração fiscal.
A31: FLXBRM-028 | B31: Retenção Percentual COFINS | C31: cofinsRate | D31: invoice.items[].withholdingTaxes[?taxType='COFINS'].rate | E31: Tributário | F31: Federal | G31: Retenções Federais | H31: WithholdingTax | I31: number | J31: Decimal percentual com 2 casas; sem símbolo % no JSON | K31: Condicional | L31: Número entre 0 e 100; máximo 4 casas se necessário; não enviar símbolo %. Validar amount = baseAmount * rate / 100. | M31: 3,00% | N31: /item; /event/billing/tax | O31: ITEM_T; EVENT_T; EVENT_BAL_IMPACTS_T | P31: c_item_fed_wht_t | Q31: Gerar somente quando houver retenção COFINS; base, percentual e valor devem vir da regra fiscal/retenção aplicada ao item. | R31: Fiscal | S31: P0 | T31: Documentado | V31: Base, alíquota e valor tributário são referência fiscal do item/evento; normalmente demandam extensão/integração fiscal.
A32: FLXBRM-029 | B32: Retenção Valor COFINS | C32: cofinsAmount | D32: invoice.items[].withholdingTaxes[?taxType='COFINS'].amount | E32: Tributário | F32: Federal | G32: Retenções Federais | H32: WithholdingTax | I32: number | J32: Decimal monetário com 2 casas; currency em BRL no contexto | K32: Condicional | L32: Valor monetário >= 0; reconciliar com baseAmount e rate, tolerância recomendada de R$ 0,01. | M32: R$ 37,50 | N32: /item; /event/billing/tax | O32: ITEM_T; EVENT_T; EVENT_BAL_IMPACTS_T | P32: c_item_fed_wht_t | Q32: Gerar somente quando houver retenção COFINS; base, percentual e valor devem vir da regra fiscal/retenção aplicada ao item. | R32: Fiscal | S32: P0 | T32: Documentado | U32: Verificar se Percentual COFINS deve ser incluído; PIS possui base/percentual/valor. | V32: Base, alíquota e valor tributário são referência fiscal do item/evento; normalmente demandam extensão/integração fiscal.
A33: FLXBRM-030 | B33: Base FUST | C33: fustBaseAmount | D33: invoice.items[].sectorFunds[?fundType='FUST'].baseAmount | E33: Tributário | F33: Federal | G33: Fundos e Contr. Set. | H33: SectorFund | I33: number | J33: Decimal monetário com 2 casas; currency em BRL no contexto | K33: Condicional | L33: Valor monetário >= 0; obrigatório quando o tributo/fundo/retenção for aplicável. | M33: A informar | N33: /item; /event/billing/tax | O33: ITEM_T; EVENT_T; EVENT_BAL_IMPACTS_T | P33: c_item_sector_fund_t | Q33: Gerar somente quando o fundo FUST for aplicável ao item; valor calculado a partir de baseAmount e rate. | R33: Fiscal | S33: P0 | T33: Pendente exemplo | U33: Completar exemplo e regra de origem antes de publicar contrato. | V33: Base, alíquota e valor tributário são referência fiscal do item/evento; normalmente demandam extensão/integração fiscal.
A34: FLXBRM-031 | B34: Percentual FUST | C34: fustRate | D34: invoice.items[].sectorFunds[?fundType='FUST'].rate | E34: Tributário | F34: Federal | G34: Fundos e Contr. Set. | H34: SectorFund | I34: number | J34: Decimal percentual com 2 casas; sem símbolo % no JSON | K34: Condicional | L34: Número entre 0 e 100; máximo 4 casas se necessário; não enviar símbolo %. Validar amount = baseAmount * rate / 100. | M34: 1,00% | N34: /item; /event/billing/tax | O34: ITEM_T; EVENT_T; EVENT_BAL_IMPACTS_T | P34: c_item_sector_fund_t | Q34: Gerar somente quando o fundo FUST for aplicável ao item; valor calculado a partir de baseAmount e rate. | R34: Fiscal | S34: P0 | T34: Documentado | V34: Base, alíquota e valor tributário são referência fiscal do item/evento; normalmente demandam extensão/integração fiscal.
A35: FLXBRM-032 | B35: Valor FUST | C35: fustAmount | D35: invoice.items[].sectorFunds[?fundType='FUST'].amount | E35: Tributário | F35: Federal | G35: Fundos e Contr. Set. | H35: SectorFund | I35: number | J35: Decimal monetário com 2 casas; currency em BRL no contexto | K35: Condicional | L35: Valor monetário >= 0; reconciliar com baseAmount e rate, tolerância recomendada de R$ 0,01. | M35: R$ 48,90 | N35: /item; /event/billing/tax | O35: ITEM_T; EVENT_T; EVENT_BAL_IMPACTS_T | P35: c_item_sector_fund_t | Q35: Gerar somente quando o fundo FUST for aplicável ao item; valor calculado a partir de baseAmount e rate. | R35: Fiscal | S35: P0 | T35: Documentado | V35: Base, alíquota e valor tributário são referência fiscal do item/evento; normalmente demandam extensão/integração fiscal.
A36: FLXBRM-033 | B36: Base FUNTTEL | C36: funttelBaseAmount | D36: invoice.items[].sectorFunds[?fundType='FUNTTEL'].baseAmount | E36: Tributário | F36: Federal | G36: Fundos e Contr. Set. | H36: SectorFund | I36: number | J36: Decimal monetário com 2 casas; currency em BRL no contexto | K36: Condicional | L36: Valor monetário >= 0; obrigatório quando o tributo/fundo/retenção for aplicável. | M36: A informar | N36: /item; /event/billing/tax | O36: ITEM_T; EVENT_T; EVENT_BAL_IMPACTS_T | P36: c_item_sector_fund_t | Q36: Gerar somente quando o fundo FUNTTEL for aplicável ao item; valor calculado a partir de baseAmount e rate. | R36: Fiscal | S36: P0 | T36: Pendente exemplo | U36: Completar exemplo e regra de origem antes de publicar contrato. | V36: Base, alíquota e valor tributário são referência fiscal do item/evento; normalmente demandam extensão/integração fiscal.
A37: FLXBRM-034 | B37: Percentual FUNTTEL | C37: funttelRate | D37: invoice.items[].sectorFunds[?fundType='FUNTTEL'].rate | E37: Tributário | F37: Federal | G37: Fundos e Contr. Set. | H37: SectorFund | I37: number | J37: Decimal percentual com 2 casas; sem símbolo % no JSON | K37: Condicional | L37: Número entre 0 e 100; máximo 4 casas se necessário; não enviar símbolo %. Validar amount = baseAmount * rate / 100. | M37: 0,50% | N37: /item; /event/billing/tax | O37: ITEM_T; EVENT_T; EVENT_BAL_IMPACTS_T | P37: c_item_sector_fund_t | Q37: Gerar somente quando o fundo FUNTTEL for aplicável ao item; valor calculado a partir de baseAmount e rate. | R37: Fiscal | S37: P0 | T37: Documentado | V37: Base, alíquota e valor tributário são referência fiscal do item/evento; normalmente demandam extensão/integração fiscal.
A38: FLXBRM-035 | B38: Valor FUNTTEL | C38: funttelAmount | D38: invoice.items[].sectorFunds[?fundType='FUNTTEL'].amount | E38: Tributário | F38: Federal | G38: Fundos e Contr. Set. | H38: SectorFund | I38: number | J38: Decimal monetário com 2 casas; currency em BRL no contexto | K38: Condicional | L38: Valor monetário >= 0; reconciliar com baseAmount e rate, tolerância recomendada de R$ 0,01. | M38: R$ 24,45 | N38: /item; /event/billing/tax | O38: ITEM_T; EVENT_T; EVENT_BAL_IMPACTS_T | P38: c_item_sector_fund_t | Q38: Gerar somente quando o fundo FUNTTEL for aplicável ao item; valor calculado a partir de baseAmount e rate. | R38: Fiscal | S38: P0 | T38: Documentado | V38: Base, alíquota e valor tributário são referência fiscal do item/evento; normalmente demandam extensão/integração fiscal.
A39: FLXBRM-036 | B39: CFOP | C39: cfop | D39: invoice.items[].fiscalOperation.cfop | E39: Tributário | F39: Classificações fiscais | G39: Class. Fiscal / Oper. | H39: FiscalOperation | I39: string | J39: Código fiscal; manter como texto | K39: Condicional | L39: Obrigatório quando houver operação fiscal; validar domínio CFOP configurado. Atenção: exemplo informado não segue padrão usual de 4 dígitos. | M39: 4838384 | N39: /product; /purchased_product | O39: PRODUCT_T; PURCHASED_PRODUCT_T | P39: c_pur_prod_fiscal_oper_t | Q39: Preencher a partir da classificação fiscal da operação do item/serviço; validar com a configuração fiscal vigente. | R39: Fiscal | S39: P0 | T39: Revisar domínio | U39: Exemplo informado parece fora do padrão usual de CFOP; validar com fiscal. | V39: Classificação fiscal/operação tende a ser atributo de produto/oferta ou extensão fiscal.
A40: FLXBRM-037 | B40: Base de cálculo ISS | C40: issBaseAmount | D40: invoice.items[].taxDetails[?taxType='ISS'].baseAmount | E40: Tributário | F40: Municipal | G40: Impostos Municipais | H40: TaxDetail | I40: number | J40: Decimal monetário com 2 casas; currency em BRL no contexto | K40: Condicional | L40: Valor monetário >= 0; obrigatório quando o tributo/fundo/retenção for aplicável. | M40: R$ 1.250,00 | N40: /item; /event/billing/tax | O40: ITEM_T; EVENT_T; EVENT_BAL_IMPACTS_T | P40: c_item_mun_tax_t | Q40: Gerar somente quando o tributo ISS for aplicável ao item; amount deve ser derivado de baseAmount e rate ou recebido de motor fiscal. | R40: Fiscal | S40: P0 | T40: Documentado | V40: Base, alíquota e valor tributário são referência fiscal do item/evento; normalmente demandam extensão/integração fiscal.
...

Sheet Resumo Dicionário
A1: Resumo do dicionário técnico-funcional
A2: Indicadores, pendências e recomendações para publicar o contrato de API/FlexBill integrado ao Oracle BRM.
A4: Indicador | B4: Valor | C4: Fórmula / Observação | E4: Domínio | F4: Qtd.
A5: Total de campos | B5: =COUNTA('Dicionário API'!A4:A73) -> 70 | C5: Total de linhas do dicionário | E5: Tributário | F5: =COUNTIF('Dicionário API'!E4:E73,E5) -> 43
A6: Campos tributários | B6: =COUNTIF('Dicionário API'!E4:E73,"Tributário") -> 43 | C6: Domínio = Tributário | E6: Não tributária | F6: =COUNTIF('Dicionário API'!E4:E73,E6) -> 27
A7: Campos não tributários | B7: =COUNTIF('Dicionário API'!E4:E73,"Não tributária") -> 27 | C7: Domínio = Não tributária
A8: Campos documentados | B8: =COUNTIF('Dicionário API'!T4:T73,"Documentado") -> 57 | C8: Status = Documentado
A9: Campos com pendência de exemplo | B9: =COUNTIF('Dicionário API'!T4:T73,"Pendente exemplo")+COUNTIF('Dicionário API'!T4:T73,"Pendente exemplo; Revisar domínio")+COUNTIF('Dicionário API'!T4:T73,"Pendente exemplo; Revisar duplicidade") -> 4 | C9: Status contém Pendente
A10: Campos para revisão | B10: =COUNTIF('Dicionário API'!T4:T73,"Revisar domínio")+COUNTIF('Dicionário API'!T4:T73,"Revisar duplicidade")+COUNTIF('Dicionário API'!T4:T73,"Pendente exemplo; Revisar domínio")+COUNTIF('Dicionário API'!T4:T73,"Pendente exemplo; Revisar duplicidade") -> 9 | C10: Status contém Revisar
A11: Campos sensíveis/dado pessoal | B11: =COUNTIF('Dicionário API'!R4:R73,"Dado pessoal") -> 9 | C11: Sensibilidade = Dado pessoal
A12: Campos P0 | B12: =COUNTIF('Dicionário API'!S4:S73,"P0") -> 50 | C12: Prioridade = P0
A13: Maturidade documental | B13: =B8/B5 -> 0.81428571 | C13: Documentados / Total
A16: Nível funcional | B16: Qtd. | E16: ID | F16: Severidade | G16: Achado | H16: Campos impactados | I16: Recomendação
A17: Customer | B17: =COUNTIF('Dicionário API'!H4:H73,A17) -> 3 | E17: PEND-001 | F17: Alta | G17: Exemplos pendentes com valor 'A informar'. | H17: Base do CBS; Retenção Base CSLL; Base FUST; Base FUNTTEL | I17: Completar exemplos reais e origem de cálculo antes de publicar o contrato.
A18: FiscalOperation | B18: =COUNTIF('Dicionário API'!H4:H73,A18) -> 2 | E18: PEND-002 | F18: Alta | G18: CFOP com exemplo fora do padrão usual de 4 dígitos. | H18: CFOP | I18: Validar com fiscal e ajustar exemplo/domínio permitido.
A19: Invoice | B19: =COUNTIF('Dicionário API'!H4:H73,A19) -> 5 | E19: PEND-003 | F19: Média | G19: Possível ausência de Percentual COFINS no grupo de impostos federais. | H19: Base de cálculo COFINS; Valor COFINS | I19: Confirmar se o campo deve existir para manter paridade com PIS.
A20: InvoiceItem | B20: =COUNTIF('Dicionário API'!H4:H73,A20) -> 8 | E20: PEND-004 | F20: Média | G20: Mensagem importante aparece em dois grupos. | H20: MENSAGEM IMPORTANTE PARA VOCÊ; Mensagem importante para você | I20: Definir origem única e reaproveitar no layout.
A21: Message | B21: =COUNTIF('Dicionário API'!H4:H73,A21) -> 2 | E21: PEND-005 | F21: Média | G21: Dados de solicitante aparecem em Emitente e Contato do solicitante. | H21: Nome/E-mail/Telefone Solicitante | I21: Confirmar se são papéis distintos ou duplicidade de layout.
A22: Payment | B22: =COUNTIF('Dicionário API'!H4:H73,A22) -> 3
A23: Requester | B23: =COUNTIF('Dicionário API'!H4:H73,A23) -> 6
A24: SectorFund | B24: =COUNTIF('Dicionário API'!H4:H73,A24) -> 9
A25: TaxDetail | B25: =COUNTIF('Dicionário API'!H4:H73,A25) -> 20
A26: WithholdingTax | B26: =COUNTIF('Dicionário API'!H4:H73,A26) -> 12
A30: Recomendação | B30: Descrição
A31: Contrato externo | B31: Manter JSON funcional, sem expor flist, PIN_FLD_* ou tabelas BRM ao consumidor.
A32: Tributos | B32: Modelar como arrays repetíveis: taxDetails[], withholdingTaxes[] e sectorFunds[].
A33: Valores | B33: Enviar monetários como number e currency no contexto; formato R$ fica para apresentação/layout.
A34: Datas | B34: Padronizar ISO 8601 na API: YYYY-MM-DD e referenceMonth como YYYY-MM.
A35: Auditoria | B35: Propagar correlationId/requestId e aplicar mascaramento para dados pessoais.

Sheet Modelo JSON
A1: Modelo JSON sugerido para a API
A2: Exemplo derivado do dicionário. Valores fiscais com null representam pontos pendentes de exemplo/origem na planilha.
A4: JSON sample
A5: {
A6: "invoice": {
A7: "invoiceNumber": "TRIAL-362046000000000000",
A8: "referenceMonth": "2026-05",
A9: "account": {
A10: "accountNumber": "2201487635"
A11: },
A12: "mainContractNumber": "1776934210",
A13: "billingPeriod": {
... A121: }

Sheet Listas Dicionário
A1: Obrigatoriedade | B1: Tipo de dado | C1: Sensibilidade | D1: Prioridade | E1: Status documentação
A2: Sim | B2: string | C2: Fiscal | D2: P0 | E2: Documentado
A3: Não | B3: number | C3: Dado pessoal | D3: P1 | E3: Pendente exemplo
A4: Condicional | B4: object | C4: Financeiro | D4: P2 | E4: Revisar domínio
B5: array | C5: Operacional | D5: P3 | E5: Revisar duplicidade
B6: boolean | C6: Interno/Comunicação | E6: Pendente exemplo; Revisar domínio
E7: Pendente exemplo; Revisar duplicidade
